<?xml version="1.0"?>

<robot xmlns:xacro="http://ros.org/wiki/xacro">

  <xacro:include filename="mecanum_wheel.gazebo.xacro"/>
  <xacro:include filename="mecanum_wheel.transmission.xacro"/>

  <xacro:macro name="mecanum_wheel" params="name separation x_offset reflect type parent">
    <link name="${name}_link">
      <visual>
        <origin xyz="0 0 0" rpy="0 0 0"/>
        <geometry>
          <xacro:if value="${type == 'left'}">
            <mesh filename="package://dyno_description/meshes/wheels/mecanum_wheel.stl" scale="0.001 0.001 0.001"/>
          </xacro:if>
          <xacro:if value="${type == 'right'}">
            <mesh filename="package://dyno_description/meshes/wheels/mecanum_wheel.stl" scale="0.001 0.001 -0.001"/>
          </xacro:if>
        </geometry>
        <material name="dark"/>
      </visual>

      <collision>
        <origin xyz="0 0 0" rpy="0 0 0"/>
        <geometry>
          <cylinder radius="0.05" length="0.05"/>
        </geometry>
        <material name="orange"/>
      </collision>

      <inertial>
        <origin xyz="0 0 ${-0.00207 * reflect}" rpy="0 0 0"/>
        <!-- TODO: update according to real wheel properties -->
        <mass value="1.0"/>
        <inertia ixx="0.00499743171" ixy="${ 0.00000004464 * reflect}" ixz="-0.00000002245"
                 iyy="0.00499741733" iyz="${-0.00000000164 * reflect}"
                 izz="0.00839239692"/>
      </inertial>

    </link>

    <joint name="${name}_joint" type="continuous">
      <origin xyz="${x_offset} ${-separation / 2 * reflect} 0" rpy="${-M_PI/2} 0 0"/>
      <parent link="${parent}"/>
      <child link="${name}_link"/>
      <axis xyz="0 0 1"/>
      <limit effort="10000" velocity="10000"/>
    </joint>

    <!-- Transmission -->

    <xacro:if value="$(arg use_ros_control_for_base)">
      <wheel_transmission name="${name}"/>
    </xacro:if>

    <!-- Gazebo extensions -->
    <mecanum_wheel_gazebo name="${name}"/>

  </xacro:macro>
</robot>
