<?xml version="1.0"?>

<robot xmlns:xacro="http://ros.org/wiki/xacro">

  <xacro:include filename="drive_wheel.gazebo.xacro"/>

  <xacro:include filename="drive_wheel.transmission.xacro"/>

  <xacro:macro name="drive_wheel" params="name separation z_offset reflect parent">
    <link name="${name}_link">
      <visual>
        <origin xyz="0 0 0" rpy="${1.57*reflect} 0 0"/>
        <geometry>
          <mesh filename="package://dyno_description/meshes/wheels/right_tire.stl" scale="0.001 0.001 0.001"/>
        </geometry>
        <material name="dark"/>
        <material name="black"/>
      </visual>

      <collision>
        <origin xyz="0 0 0" rpy="0 0 0"/>
        <geometry>
          <cylinder length="0.018" radius="0.033"/>
        </geometry>
        <material name="orange"/>
      </collision>

      <inertial>
        <origin xyz="0 0 0" />
        <mass value="2.8498940e-02" />
        <inertia ixx="1.1175580e-05" ixy="-4.2369783e-11" ixz="-5.9381719e-09"
                 iyy="1.1192413e-05" iyz="-1.4400107e-11"
                 izz="2.0712558e-05" />
        </inertial>
    </link>

    <joint name="${name}_joint" type="continuous">
      <origin xyz="0 ${-separation / 2 * reflect} ${z_offset}" rpy="${-pi/2} 0 0"/>
      <parent link="${parent}"/>
      <child link="${name}_link"/>
      <axis xyz="0 0 1"/>
      <limit effort="10000" velocity="10000"/>
    </joint>

    <!-- Transmission -->
    <xacro:if value="$(arg use_ros_control_for_base)">
      <wheel_transmission name="${name}"/>
    </xacro:if>

    <!-- Gazebo extensions -->
    <drive_wheel_gazebo name="${name}"/>

  </xacro:macro>
</robot>
